<?xml version="1.0" ?>
<!-- =================================================================================== -->
<!-- |    This document was autogenerated by xacro from isaac_v1.urdf.xacro            | -->
<!-- |    EDITING THIS FILE BY HAND IS NOT RECOMMENDED                                 | -->
<!-- =================================================================================== -->
<robot name="basic_mobile_bot">
  <link name="base_footprint"/>
  <joint name="base_joint" type="fixed">
    <parent link="base_footprint"/>
    <child link="base_link"/>
    <origin rpy="0 0 0" xyz="0.0 0.0 0.075"/>
  </joint>
  <!-- ********************** ROBOT BASE *********************************  -->
  <link name="base_link">
    <visual>
      <origin rpy="1.5707963267949 0 3.141592654" xyz="0.45 -0.285 0.125"/>
      <geometry>
        <mesh filename="package://recs_robot/meshes/AMR_final(mm).stl" scale="0.001 0.001 0.001"/>
      </geometry>
    </visual>
    <collision>
      <origin rpy="1.5707963267949 0 3.141592654" xyz="0.45 -0.285 0.125"/>
      <geometry>
        <mesh filename="package://recs_robot/meshes/AMR_final(mm).stl" scale="0.001 0.001 0.001"/>
      </geometry>
    </collision>
    <inertial>
      <origin rpy="1.5707963267948966 0 1.5707963267948966" xyz="0 0 0"/>
      <mass value="15"/>
      <inertia ixx="1.44028125" ixy="0.0" ixz="0.0" iyy="1.4045" iyz="0.0" izz="0.81978125"/>
    </inertial>
  </link>
  <!-- *********************** DRIVE WHEELS ******************************  -->
  <link name="drivewhl_l_link">
    <visual>
      <origin rpy="1.5707963267949 0 0" xyz="0 0 0"/>
      <geometry>
        <cylinder length="0.06" radius="0.075"/>
      </geometry>
      <material name="White">
        <color rgba="1.0 1.0 1.0 1.0"/>
      </material>
    </visual>
    <collision>
      <origin rpy="1.5707963267948966 0 0" xyz="0 0 0"/>
      <geometry>
        <cylinder length="0.06" radius="0.075"/>
      </geometry>
    </collision>
    <inertial>
      <origin rpy="1.5707963267948966 0 0" xyz="0 0 0"/>
      <mass value="110.5"/>
      <inertia ixx="0.188540625" ixy="0" ixz="0" iyy="0.188540625" iyz="0" izz="0.31078125"/>
    </inertial>
  </link>
  <joint name="drivewhl_l_joint" type="revolute">
    <parent link="base_link"/>
    <child link="drivewhl_l_link"/>
    <origin rpy="0 0 0" xyz="-0.0 0.24 0.0"/>
    <limit effort="30" lower="-inf" upper="inf" velocity="5.0"/>
    <axis xyz="0 1 0"/>
  </joint>
  <link name="drivewhl_r_link">
    <visual>
      <origin rpy="1.5707963267949 0 0" xyz="0 0 0"/>
      <geometry>
        <cylinder length="0.06" radius="0.075"/>
      </geometry>
      <material name="White">
        <color rgba="1.0 1.0 1.0 1.0"/>
      </material>
    </visual>
    <collision>
      <origin rpy="1.5707963267948966 0 0" xyz="0 0 0"/>
      <geometry>
        <cylinder length="0.06" radius="0.075"/>
      </geometry>
    </collision>
    <inertial>
      <origin rpy="1.5707963267948966 0 0" xyz="0 0 0"/>
      <mass value="110.5"/>
      <inertia ixx="0.188540625" ixy="0" ixz="0" iyy="0.188540625" iyz="0" izz="0.31078125"/>
    </inertial>
  </link>
  <joint name="drivewhl_r_joint" type="revolute">
    <parent link="base_link"/>
    <child link="drivewhl_r_link"/>
    <origin rpy="0 0 0" xyz="-0.0 -0.24 0.0"/>
    <limit effort="30" lower="-inf" upper="inf" velocity="5.0"/>
    <axis xyz="0 1 0"/>
  </joint>
  <!-- *********************** Caster ******************************  -->
  <link name="caster_lf_link">
    <visual>
      <origin rpy="1.5707963267949 0 0" xyz="0 0 0"/>
      <geometry>
        <cylinder length="0.04" radius="0.06"/>
      </geometry>
      <material name="White">
        <color rgba="1.0 1.0 1.0 1.0"/>
      </material>
    </visual>
    <collision>
      <origin rpy="1.5707963267948966 0 0" xyz="0 0 0"/>
      <geometry>
        <cylinder length="0.04" radius="0.06"/>
      </geometry>
    </collision>
    <inertial>
      <origin rpy="1.5707963267948966 0 0" xyz="0 0 0"/>
      <mass value="80.5"/>
      <inertia ixx="0.08318333333333333" ixy="0" ixz="0" iyy="0.08318333333333333" iyz="0" izz="0.1449"/>
    </inertial>
  </link>
  <joint name="caster_lf_joint" type="fixed">
    <parent link="base_link"/>
    <child link="caster_lf_link"/>
    <origin rpy="0 0 0" xyz="0.35 0.1425 -0.01"/>
    <limit effort="0" lower="-3.1415" upper="3.1415" velocity="5.0"/>
    <axis xyz="0 1 0"/>
  </joint>
  <link name="caster_rf_link">
    <visual>
      <origin rpy="1.5707963267949 0 0" xyz="0 0 0"/>
      <geometry>
        <cylinder length="0.04" radius="0.06"/>
      </geometry>
      <material name="White">
        <color rgba="1.0 1.0 1.0 1.0"/>
      </material>
    </visual>
    <collision>
      <origin rpy="1.5707963267948966 0 0" xyz="0 0 0"/>
      <geometry>
        <cylinder length="0.04" radius="0.06"/>
      </geometry>
    </collision>
    <inertial>
      <origin rpy="1.5707963267948966 0 0" xyz="0 0 0"/>
      <mass value="80.5"/>
      <inertia ixx="0.08318333333333333" ixy="0" ixz="0" iyy="0.08318333333333333" iyz="0" izz="0.1449"/>
    </inertial>
  </link>
  <joint name="caster_rf_joint" type="fixed">
    <parent link="base_link"/>
    <child link="caster_rf_link"/>
    <origin rpy="0 0 0" xyz="0.35 -0.1425 -0.01"/>
    <limit effort="0" lower="-3.1415" upper="3.1415" velocity="5.0"/>
    <axis xyz="0 1 0"/>
  </joint>
  <link name="caster_lb_link">
    <visual>
      <origin rpy="1.5707963267949 0 0" xyz="0 0 0"/>
      <geometry>
        <cylinder length="0.04" radius="0.06"/>
      </geometry>
      <material name="White">
        <color rgba="1.0 1.0 1.0 1.0"/>
      </material>
    </visual>
    <collision>
      <origin rpy="1.5707963267948966 0 0" xyz="0 0 0"/>
      <geometry>
        <cylinder length="0.04" radius="0.06"/>
      </geometry>
    </collision>
    <inertial>
      <origin rpy="1.5707963267948966 0 0" xyz="0 0 0"/>
      <mass value="80.5"/>
      <inertia ixx="0.08318333333333333" ixy="0" ixz="0" iyy="0.08318333333333333" iyz="0" izz="0.1449"/>
    </inertial>
  </link>
  <joint name="caster_lb_joint" type="fixed">
    <parent link="base_link"/>
    <child link="caster_lb_link"/>
    <origin rpy="0 0 0" xyz="-0.35 0.1425 -0.01"/>
    <limit effort="0" lower="-3.1415" upper="3.1415" velocity="5.0"/>
    <axis xyz="0 1 0"/>
  </joint>
  <link name="caster_rb_link">
    <visual>
      <origin rpy="1.5707963267949 0 0" xyz="0 0 0"/>
      <geometry>
        <cylinder length="0.04" radius="0.06"/>
      </geometry>
      <material name="White">
        <color rgba="1.0 1.0 1.0 1.0"/>
      </material>
    </visual>
    <collision>
      <origin rpy="1.5707963267948966 0 0" xyz="0 0 0"/>
      <geometry>
        <cylinder length="0.04" radius="0.06"/>
      </geometry>
    </collision>
    <inertial>
      <origin rpy="1.5707963267948966 0 0" xyz="0 0 0"/>
      <mass value="80.5"/>
      <inertia ixx="0.08318333333333333" ixy="0" ixz="0" iyy="0.08318333333333333" iyz="0" izz="0.1449"/>
    </inertial>
  </link>
  <joint name="caster_rb_joint" type="fixed">
    <parent link="base_link"/>
    <child link="caster_rb_link"/>
    <origin rpy="0 0 0" xyz="-0.35 -0.1425 -0.01"/>
    <limit effort="0" lower="-3.1415" upper="3.1415" velocity="5.0"/>
    <axis xyz="0 1 0"/>
  </joint>
  <joint name="imu_joint" type="fixed">
    <parent link="base_link"/>
    <child link="imu_link"/>
    <origin rpy="0 0 0" xyz="0 0 0.13"/>
  </joint>
  <link name="imu_link"/>
  <joint name="lidarf_joint" type="fixed">
    <parent link="base_link"/>
    <child link="lidarf_link"/>
    <origin rpy="0 0 0" xyz="0.41 -0.24 0.140"/>
  </joint>
  <link name="lidarf_link"/>
  <joint name="lidarb_joint" type="fixed">
    <parent link="base_link"/>
    <child link="lidarb_link"/>
    <origin rpy="0 0 0" xyz="-0.41 0.24 0.140"/>
  </joint>
  <link name="lidarb_link"/>
  <joint name="lidar_joint3" type="fixed">
    <origin rpy="0 0 0.0" xyz="0.0 0.0 0.140"/>
    <parent link="base_link"/>
    <child link="lidar_merged"/>
  </joint>
  <link name="lidar_merged"/>
</robot>
