<?xml version="1.0" ?>
<robot name="basic_mobile_bot" xmlns:xacro="http://ros.org/wiki/xacro">

  <xacro:property name="base_width" value="0.56"/>
  <xacro:property name="base_length" value="0.9"/>
  <xacro:property name="base_height" value="0.585"/>

  <xacro:property name="wheel_radius" value="0.075"/>
  <xacro:property name="wheel_width" value="0.06"/>
  <xacro:property name="wheel_ygap" value="0.24"/>
  <xacro:property name="wheel_zoff" value="0.0"/>
  <xacro:property name="wheel_xoff" value="0.0"/>

  <xacro:property name="caster_radius" value="0.06"/>
  <xacro:property name="caster_width" value="0.04"/>
  <xacro:property name="caster_xoff" value="0.35"/>
  <xacro:property name="caster_ygap" value="0.1425"/>
  <xacro:property name="caster_zoff" value="0.015"/>

  <xacro:macro name="box_inertia" params="m w h d">
    <inertial>
      <origin xyz="0 0 0" rpy="${pi/2} 0 ${pi/2}"/>
      <mass value="${m}"/>
      <inertia ixx="${(m/12) * (h*h + d*d)}" ixy="0.0" ixz="0.0" iyy="${(m/12) * (w*w + d*d)}" iyz="0.0" izz="${(m/12) * (w*w + h*h)}"/>
    </inertial>
  </xacro:macro>

  <xacro:macro name="cylinder_inertia" params="m r h">
    <inertial>
      <origin xyz="0 0 0" rpy="${pi/2} 0 0" />
      <mass value="${m}"/>
      <inertia ixx="${(m/12) * (3*r*r + h*h)}" ixy = "0" ixz = "0" iyy="${(m/12) * (3*r*r + h*h)}" iyz = "0" izz="${(m/2) * (r*r)}"/>
    </inertial>
  </xacro:macro>

  <link name="base_footprint"/>

  <joint name="base_joint" type="fixed">
    <parent link="base_footprint"/>
    <child link="base_link" />
    <origin xyz="0.0 0.0 ${wheel_radius}" rpy="0 0 0"/>
  </joint>

  <!-- ********************** ROBOT BASE *********************************  -->
  <link name="base_link">
    <visual>
      <origin xyz="0.0 0.0 0.225" rpy="1.5707963267949 0 3.141592654"/>
      <geometry>
        <box size="${base_length} ${base_width} ${base_height}"/>
      </geometry>
    </visual>
    <collision>
      <origin xyz="0.0 0.0 0.225" rpy="1.5707963267949 0 3.141592654"/>
      <geometry>
        <box size="${base_length} ${base_width} ${base_height}"/>
      </geometry>
    </collision>

    <xacro:box_inertia m="15" w="${base_width}" d="${base_length}" h="${base_height}"/>

  </link>

  <!-- *********************** DRIVE WHEELS ******************************  -->

  <xacro:macro name="wheel" params="prefix x_reflect y_reflect">
    <link name="${prefix}_link">
      <visual>
        <origin xyz="0 0 0" rpy="1.5707963267949 0 0"/>
        <geometry>
            <cylinder radius="${wheel_radius}" length="${wheel_width}"/>
        </geometry>
        <material name="White">
          <color rgba="${255/255} ${255/255} ${255/255} 1.0"/>
        </material>
      </visual>
      
      <collision>
        <origin xyz="0 0 0" rpy="${pi/2} 0 0"/>
        <geometry>
          <cylinder radius="${wheel_radius}" length="${wheel_width}"/>
        </geometry>
      </collision>
      
      <xacro:cylinder_inertia m="110.5" r="${wheel_radius}" h="${wheel_width}"/>
      
    </link>

    <joint name="${prefix}_joint" type="revolute">
      <parent link="base_link"/>
      <child link="${prefix}_link"/>
      <origin xyz="${x_reflect*wheel_xoff} ${y_reflect*wheel_ygap} ${-wheel_zoff}" rpy="0 0 0"/>
      <limit upper="3.1415" lower="-3.1415" effort="30" velocity="5.0"/>
      <axis xyz="0 1 0"/>
    </joint>
  </xacro:macro>

  <xacro:wheel prefix="drivewhl_l" x_reflect="-1" y_reflect="1" />
  <xacro:wheel prefix="drivewhl_r" x_reflect="-1" y_reflect="-1" />

  <!-- *********************** Caster ******************************  -->

  <xacro:macro name="caster" params="prefix x_reflect y_reflect">
    <link name="${prefix}_link">
      <visual>
        <origin xyz="0 0 0" rpy="1.5707963267949 0 0"/>
        <geometry>
            <cylinder radius="${caster_radius}" length="${caster_width}"/>
        </geometry>
        <material name="White">
          <color rgba="${255/255} ${255/255} ${255/255} 1.0"/>
        </material>
      </visual>
      
      <collision>
        <origin xyz="0 0 0" rpy="${pi/2} 0 0"/>
        <geometry>
          <cylinder radius="${caster_radius}" length="${caster_width}"/>
        </geometry>
      </collision>
      <xacro:cylinder_inertia m="80.5" r="${caster_radius}" h="${caster_width}"/>
    </link>

    <joint name="${prefix}_joint" type="revolute">
      <parent link="base_link"/>
      <child link="${prefix}_link"/>
      <origin xyz="${x_reflect*caster_xoff} ${y_reflect*caster_ygap} ${-caster_zoff}" rpy="0 0 0"/>
      <limit upper="3.1415" lower="-3.1415" effort="30" velocity="5.0"/>
      <axis xyz="0 1 0"/>
    </joint>
  </xacro:macro>

  <xacro:caster prefix="caster_lf" x_reflect="1" y_reflect="1"/>
  <xacro:caster prefix="caster_rf" x_reflect="1" y_reflect="-1"/>
  <xacro:caster prefix="caster_lb" x_reflect="-1" y_reflect="1"/>
  <xacro:caster prefix="caster_rb" x_reflect="-1" y_reflect="-1"/>

  <joint name="imu_joint" type="fixed">
    <parent link="base_link"/>
    <child link="imu_link"/>
    <origin xyz="0 0 0.13" rpy="0 0 0"/>
  </joint>

  <link name="imu_link"/>

  <joint name="lidarf_joint" type="fixed">
    <parent link="base_link"/>
    <child link="lidarf_link"/>
    <origin xyz="0.417 -0.247 0.140" rpy="0 0 2.3558"/>
  </joint>

  <link name="lidarf_link"/>

  <joint name="lidarb_joint" type="fixed">
    <parent link="base_link"/>
    <child link="lidarb_link"/>
    <origin xyz="-0.417 0.247 0.140" rpy="0 0 -0.785"/>
  </joint>

  <link name="lidarb_link"/>

  <joint name="lidar_joint3" type="fixed">
    <origin rpy="0 0 0.0" xyz="0.0 0.0 0.140"/>
    <parent link="base_link"/>
    <child link="lidar_merged"/>
  </joint>

  <link name="lidar_merged"/>


</robot>
